Traceback (most recent call last):
  File "/users/mhowison/miniconda/envs/hivmmer/lib/python3.6/site-packages/pandas/core/indexing.py", line 1506, in _has_valid_type
    error()
  File "/users/mhowison/miniconda/envs/hivmmer/lib/python3.6/site-packages/pandas/core/indexing.py", line 1501, in error
    axis=self.obj._get_axis_name(axis)))
KeyError: 'the label [0] is not in the [index]'

During handling of the above exception, another exception occurred:

Traceback (most recent call last):
  File "lib/calls.py", line 39, in <module>
    calls.loc[(i, codon), method] = codons.loc[i, codon]
  File "/users/mhowison/miniconda/envs/hivmmer/lib/python3.6/site-packages/pandas/core/indexing.py", line 1367, in __getitem__
    return self._getitem_tuple(key)
  File "/users/mhowison/miniconda/envs/hivmmer/lib/python3.6/site-packages/pandas/core/indexing.py", line 858, in _getitem_tuple
    return self._getitem_lowerdim(tup)
  File "/users/mhowison/miniconda/envs/hivmmer/lib/python3.6/site-packages/pandas/core/indexing.py", line 991, in _getitem_lowerdim
    section = self._getitem_axis(key, axis=i)
  File "/users/mhowison/miniconda/envs/hivmmer/lib/python3.6/site-packages/pandas/core/indexing.py", line 1626, in _getitem_axis
    self._has_valid_type(key, axis)
  File "/users/mhowison/miniconda/envs/hivmmer/lib/python3.6/site-packages/pandas/core/indexing.py", line 1514, in _has_valid_type
    error()
  File "/users/mhowison/miniconda/envs/hivmmer/lib/python3.6/site-packages/pandas/core/indexing.py", line 1501, in error
    axis=self.obj._get_axis_name(axis)))
KeyError: 'the label [0] is not in the [index]'
